Workbook

Sheet FAQ
A1: WABI THERAPY — 50 CÂU HỎI THƯỜNG GẶP
A2: Ngân hàng câu trả lời chuẩn dùng cho website, inbox và mạng xã hội. Đối tượng: 17–35 tuổi.
A4: STT | B4: Nhóm chủ đề | C4: Câu hỏi | D4: Câu trả lời | E4: Ưu tiên | F4: Kênh sử dụng | G4: Comment | H4: Sửa lại
A5: 1 | B5: Bắt đầu | C5: Tham vấn tâm lý là gì? | D5: Tham vấn/trị liệu (counseling/psychotherapy) là quá trình điều trị liên tục nhằm giải quyết vấn đề tâm lý, cải thiện sức khỏe tinh thần và phát triển cá nhân, thông qua đối thoại và các kỹ thuật chuyên biệt. Đây không phải là nơi ai đó khuyên bạn phải làm gì — mà là nơi bạn được lắng nghe và cùng tìm ra hướng đi của chính mình. | E5: Cao | F5: Website · Inbox | G5: Nên tách tham vấn và trị liệu riêng; không dùng từ liên quan tới bệnh lí như "điều trị"; thống nhất sử dụng "sức khỏe tâm thần" thay cho "sức khỏe tinh thần" | H5: 1/ Tham vấn tâm lý là quá trình trò chuyện giữa bạn và chuyên gia nhằm làm rõ, tháo gỡ những khó khăn hoặc khúc mắc cụ thể đang diễn ra trong cuộc sống hiện tại. Tham vấn tâm lý sẽ giúp bạn: - Định hình vấn đề: Nhìn nhận bức tranh toàn cảnh về khó khăn bạn đang gặp phải một cách khách quan. - Tìm kiếm giải pháp: Xác định mục tiêu, khai phá tiềm năng bản thân và đưa ra các quyết định sáng suốt. - Rèn luyện kỹ năng: Trang bị các kỹ năng thực tế như quản lý cảm xúc, ứng phó với căng thẳng, cải thiện giao tiếp hoặc giải quyết mâu thuẫn. Thông tin dịch vụ: Vấn đề phù hợp: Căng thẳng công việc/học tập, áp lực thi cử, mâu thuẫn quan hệ (bạn bè, đồng nghiệp, người yêu), định hướng bản thân, khủng hoảng tuổi trưởng thành, khám phá xu hướng tính dục... Thời lượng: thường ngắn hạn (từ 1 đến vài buổi tùy nhu cầu). Hình thức: tham vấn cá nhân, cặp đôi hoặc gia đình (trực tiếp hoặc online). 2/ Trị liệu tâm lý là quá trình đồng hành chuyên sâu giữa bạn và nhà trị liệu nhằm thấu hiểu, xoa dịu các tổn thương tinh thần và giải quyết các rối nhiễu tâm lý. Khác với tham vấn ngắn hạn (thường tập trung vào giải quyết vấn đề hiện tại), trị liệu tâm lý sẽ giúp bạn: - Khám phá gốc rễ: Kết nối các trải nghiệm trong quá khứ (trải nghiệm tuổi thơ, các biến cố) với suy nghĩ, cảm xúc và hành vi hiện tại. - Tạo sự thay đổi bền vững: Xây dựng cơ chế ứng phó lành mạnh và nâng cao năng lực tự chữa lành trước những khó khăn trong cuộc sống. Các vấn đề: trầm cảm, lo âu, rối loạn hoảng sợ, rối loạn căng thẳng sang chấn, rối loạn ăn uống, các rối loạn nhân cách, căng thẳng mạn tính... Đối tượng: Trẻ em, thanh thiếu niên, người trưởng thành và người cao tuổi. Hình thức: Trị liệu cá nhân, cặp đôi/vợ chồng, gia đình hoặc trị liệu nhóm. Thời lượng: Ngắn hạn (4-6 buổi) hoặc dài hạn tùy thuộc vào nhu cầu và tình trạng thực tế của bạn.
A6: 2 | B6: Bắt đầu | C6: Đánh giá tâm lý là gì? Khác gì tham vấn/trị liệu tâm lý? | D6: Đánh giá tâm lý là quá trình sử dụng các bài kiểm tra và công cụ chuẩn hóa để thu thập thông tin về năng lực nhận thức, tính cách, cảm xúc và hành vi của bạn. Nó giống như một 'bản đồ' về tình trạng hiện tại. Còn tham vấn/trị liệu là hành trình đồng hành lâu dài để thay đổi. Bạn có thể làm đánh giá trước rồi mới trị liệu, hoặc vào thẳng trị liệu — therapist sẽ đánh giá trong quá trình nếu cần. | E6: Cao | F6: Website · Inbox | G6: Sủa từ "năng lực nhận thức" thành "đặc điểm nhận thức..." | H6: Đánh giá tâm lý là quá trình thu thập và phân tích thông tin một cách toàn diện nhằm xác định rõ tình trạng sức khỏe tâm thần, đặc điểm tâm lý, tính cách hoặc năng lực trí tuệ của một cá nhân. Quá trình đánh giá thường bao gồm: - Phỏng vấn lâm sàng: Trao đổi trực tiếp về lịch sử cá nhân, các mối bận tâm và biểu hiện hiện tại. - Sử dụng trắc nghiệm/thang đo chuẩn hóa: Thực hiện các bài test tâm lý uy tín (đo lường mức độ trầm cảm, lo âu, stress, trắc nghiệm nhân cách, trí tuệ IQ/EQ, sự tập trung chú ý...). - Quan sát & Phân tích: Ghi nhận hành vi, phản ứng và tổng hợp dữ liệu để đưa ra kết luận chuyên môn. Thông tin dịch vụ: - Trường hợp phù hợp: Khi bạn muốn hiểu rõ tình trạng sức khỏe tâm thần của mình; nghi ngờ có các triệu chứng rối loạn; cần hồ sơ đánh giá cho học tập/công việc; hoặc muốn định hướng lộ trình trị liệu chính xác. - Kết quả nhận được: Báo cáo đánh giá chi tiết kèm theo khuyến nghị/định hướng chuyên môn từ nhà tâm lý. Thời lượng: Thường diễn ra trong 1–2 buổi (bao gồm thời gian thực hiện bài test và trả kết quả/tham vấn). Đánh giá tâm lý không phải là "dán nhãn", mà là công cụ giúp bạn thấu hiểu bản thân một cách khoa học và tìm ra giải pháp nâng cao chất lượng cuộc sống.
A7: 3 | B7: Bắt đầu | C7: Mình có 'đủ nặng' để đi therapy không? | D7: Bạn không cần phải chờ đến khi mọi thứ tệ đi mới được tìm đến sự hỗ trợ. Therapy không chỉ dành cho khủng hoảng — nó cũng dành cho việc hiểu bản thân, cải thiện mối quan hệ, hay đơn giản là có một nơi an toàn để nói ra. Nếu bạn đang phân vân, đó thường đã là dấu hiệu bạn cần một khoảng lặng cho mình rồi. | E7: Cao | F7: Website · Social | G7: Câu hỏi: Thêm từ "Vấn đề của mình" Câu trả lời: sửa lại một tí về cách viết. | H7: Bạn không cần chờ đến khi khủng hoảng mới tìm kiếm sự hỗ trợ. Therapy không chỉ dành cho những tổn thương hay vấn đề bệnh lí nghiêm trọng, mà còn là không gian an toàn giúp bạn thấu hiểu bản thân, cải thiện các mối quan hệ hay đơn giản là trút bỏ gánh nặng tinh thần. Nếu bạn đang băn khoăn câu hỏi này, đó đã là dấu hiệu cho thấy tâm trí bạn đang cần một khoảng nghỉ và sự đồng hành.
A8: 4 | B8: Bắt đầu | C8: Mình chưa sẵn sàng, có sao không? | D8: Hoàn toàn không sao. Bạn cứ thoải mái suy nghĩ nhé. Hãy đi therapy khi bạn sẵn sàng. Bao giờ muốn lên lịch, chỉ cần nhắn — Wabi sẽ book giúp bạn. Và nếu có câu hỏi gì không liên quan đến tham vấn, hoặc tình huống cần giúp đỡ, bạn cũng cứ nhắn nhé. | E8: Cao | F8: Inbox | H8: Hoàn toàn không sao cả. Therapy chỉ thật sự hiệu quả khi bạn cảm thấy thoải mái và sẵn sàng mở lòng, vì vậy hãy cho bản thân thời gian nhé. Bất cứ khi nào bạn cần giải đáp thắc mắc, tìm hiểu thêm thông tin hoặc sẵn sàng đặt lịch, Wabi luôn ở đây để hỗ trợ bạn.
A9: 5 | B9: Bắt đầu | C9: Làm sao để bắt đầu với Wabi? | D9: Chỉ cần nhắn cho Wabi qua Facebook, Instagram. Bạn chia sẻ một chút về tuổi, nơi sinh sống và vấn đề đang gặp phải, admin sẽ tư vấn therapist và dịch vụ phù hợp. Sau đó bạn trả lời vài câu hỏi screening ngắn, Wabi gửi lịch qua email, bạn xác nhận là xong. | E9: Cao | F9: Website · Inbox
A10: 6 | B10: Bắt đầu | C10: Buổi đầu tiên sẽ diễn ra như thế nào? | D10: Buổi đầu là để bạn và therapist làm quen. Bạn chia sẻ mục tiêu và kỳ vọng (nếu có); therapist sẽ trao đổi về kế hoạch can thiệp và cách tiếp cận của họ — mỗi người mỗi khác — cùng các hướng giải quyết có thể. Bạn không cần chuẩn bị gì hoàn hảo cả, chỉ cần đến đúng như bạn đang là. | E10: Cao | F10: Website · Inbox | H10: Buổi gặp đầu tiên (thường là buổi lắng nghe & đánh giá ban đầu) diễn ra rất nhẹ nhàng và không có bất kỳ áp lực nào. Bạn có thể hình dung buổi này gồm 3 phần chính: - Kết nối và thiết lập không gian an toàn: therapist sẽ giới thiệu về bản thân và các nguyên tắc bảo mật, tạo không gian thoải mái để bạn làm quen. - Chia sẻ và lắng nghe: bạn chia sẻ về câu chuyện của mình và những khó khăn, băn khoăn hoặc lý do khiến bạn tìm đến therapy. - Định hướng tiếp theo: therapist giúp bạn làm rõ vấn đề, thảo luận về mục tiêu mong muốn và đề xuất tiến trình đồng hành phù hợp nhất Note: bạn không bắt buộc phải kể hết mọi câu chuyện hay bí mật ngay trong buổi đầu tiên. Hãy chia sẻ theo tốc độ mà bạn cảm thấy sẵn sàng nhất.
A11: 7 | B11: Bắt đầu | C11: Mình nên chuẩn bị gì trước buổi đầu? | D11: 1) Xác định mục tiêu: bạn muốn giải quyết vấn đề gì, mong đạt được gì. 2) Ghi lại các sự kiện, tình huống cụ thể để trình bày rõ ràng. 3) Cởi mở và trung thực — điều này giúp therapist hỗ trợ đúng hơn. 4) Chuẩn bị danh sách câu hỏi/quan ngại. 5) Giữ tâm lý thoải mái, đây là không gian an toàn. 6) Mang sổ ghi chép hoặc thiết bị ghi âm nếu bạn thấy cần. | E11: Cao | F11: Website · Inbox | H11: Bạn không cần phải chuẩn bị quá nhiều hay học thuộc lòng bất kỳ điều gì trước buổi gặp đầu tiên. Việc quan trọng nhất là mang theo một tâm trí cởi mở. Tuy nhiên, bạn cũng có thể chuẩn bị trước một chút để tự tin hơn: - Liệt kê nhanh các vấn đề: phác thảo ngắn gọn những điều đang khiến bạn bận tâm, cảm xúc bạn đang trải qua hoặc lý do chính khiến bạn tìm đến therapy. - Xác định mong muốn: suy nghĩ xem bạn hy vọng nhận được điều gì sau quá trình này (ví dụ: giảm bớt căng thẳng/lo âu, hiểu rõ bản thân, cải thiện mối quan hệ...). - Ghi lại các thắc mắc: chuẩn bị sẵn những câu hỏi bạn muốn hỏi nhà trị liệu (về phương pháp, bảo mật, quy trình...). - sắp xếp không gian phù hợp (khi gặp online): Chọn một góc riêng tư, yên tĩnh, chuẩn bị tai nghe và kết nối internet ổn định. - Mang theo cuốn sổ tay để ghi chép lại những thông tin bạn thấy quan trọng Nhớ rằng: lhông có câu trả lời nào là đúng hay sai. Bạn hoàn toàn có thể đến buổi gặp chỉ với sự mơ hồ, therapist sẽ cùng bạn làm rõ từng chút một.
A12: 8 | B12: Dịch vụ | C12: Wabi có những dịch vụ nào? | D12: Wabi có 5 nhóm dịch vụ: (1) Tham vấn & Trị liệu tâm lý, (2) Đánh giá tâm lý, (3) Tham vấn cặp đôi, (4) Art Therapy, (5) Hướng nghiệp. Tất cả đều có hình thức online và một số có offline tại Hà Nội và TP.HCM. | E12: Cao | F12: Website | G12: (1) ghi rõ là tham vấn và trị liệu tâm lí cá nhân nhen | H12: Wabi có 5 nhóm dịch vụ: (1) Tham vấn & Trị liệu tâm lý cá nhân (2) Đánh giá tâm lý (3) Tham vấn cặp đôi (4) Art Therapy (5) Hướng nghiệp Tất cả các dịch vụ đều có hình thức online và một số có offline tại Hà Nội và TP.HCM.
A13: 9 | B13: Dịch vụ | C13: Wabi hỗ trợ những vấn đề gì? | D13: Về bản ngã: phát triển bản thân, lòng tự trọng, phong cách gắn bó, khủng hoảng hiện sinh, ranh giới cá nhân. Về bệnh lý: trầm cảm, lo âu, ADHD, BPD, PTSD/C-PTSD, OCD, rối loạn lưỡng cực, ám sợ xã hội. Ngoài ra: tổn thương thời thơ ấu, đau buồn & mất mát, vấn đề mối quan hệ (tình yêu, gia đình, công việc). | E13: Cao | F13: Website · Inbox | G13: Chia lại các nhóm nhỏ cụ thể hơn | H13: Wabi đồng hành và hỗ trợ bạn giải quyết đa dạng các khó khăn tâm lý, được phân nhóm cụ thể như sau: 1/ Sức khỏe tâm thần và các rối loạn tâm lý: - Trầm cảm, các dạng rối loạn lo âu, ám sợ xã hội, rối loạn ám ảnh cưỡng chế (OCD), rối loạn lưỡng cực, - Chú ý & Hành vi: ADHD, khó khăn trong quản lý cảm xúc và tập trung. - Rối loạn nhân cách (BPD,...). 2/ Chữa lành tổn thương và khủng hoảng tâm lý: tổn thương thời thơ ấu và các trải nghiệm tiêu cực trong quá khứ; sang chấn tâm lý (PTSD/C-PTSD); đau buồn, mất mát (chia tay, mất người thân, mất mát công việc/mục tiêu). 3/ Phát triển bản thân và nhận thức nội tâm: xây dựng lòng tự trọng, sự tự tin và xác định ranh giới cá nhân; xác định phong cách gắn bó; khủng hoảng hiện sinh, mất định hướng sống, áp lực trưởng thành 4/ Mối quan hệ môi trường sống: mâu thuẫn và khó khăn trong tình yêu, đời sống hôn nhân/gia đình; áp lực công việc, học tập, kiệt sức (burnout), giao tiếp và ứng xử xã hội. Note: Nếu vấn đề của bạn không nằm trong danh sách trên, cũng đừng ngần ngại liên hệ để chúng tôi lắng nghe và tư vấn hướng hỗ trợ phù hợp nhất.
A14: 10 | B14: Dịch vụ | C14: Một buổi tham vấn kéo dài bao lâu? | D14: Thông thường 60 phút cho tham vấn cá nhân và đánh giá tâm lý. Với tham vấn cặp đôi, các buổi chung kéo dài 90 phút. | E14: Cao | F14: Website · Inbox | H14: Thời lượng tiêu chuẩn cho mỗi phiên đánh giá tâm lý, tham vấn/trị liệu tâm lý cá nhân là 60 phút. Với tham vấn cặp đôi, các phiên chung với cả hai người thường kéo dài 90 phút.
A15: 12 | B15: Dịch vụ | C15: Chương trình Hướng nghiệp gồm những gì? | D15: Gói Cơ bản (2 buổi): bạn làm test năng lực, trò chuyện với therapist về định hướng, và nhận báo cáo cùng lời khuyên về kết quả test. Gói Chuyên sâu (3 buổi): có thêm một buổi lên kế hoạch cụ thể để thực hiện định hướng đó. Nếu trong quá trình bạn có vấn đề tâm lý liên quan (self-esteem, động lực, cảm xúc...), therapist sẽ gợi ý làm thêm buổi riêng ngoài chương trình. | E15: Trung bình | F15: Website · Inbox | H15: Chương trình hướng nghiệp của Wabi được thiết kế theo lộ trình cá nhân hóa, gồm 2 gói lựa chọn linh hoạt tùy theo nhu cầu của bạn: Gói cơ bản (2 buổi) – Khám phá và định hình: bạn sẽ - Thực hiện bài test được chuẩn hóa về năng lực và thiên hướng nghề nghiệp. - Làm việc 1:1 cùng chuyên gia để phân tích kết quả và định hướng nghề nghiệp. - Nhận Báo cáo đánh giá chi tiết kèm lời khuyên chuyên môn. Gói chuyên sâu (3 buổi) – định hình và lập kế hoạch: - Bao gồm toàn bộ nội dung của gói cơ bản. - Bổ sung 1 buổi chuyên sâu: chuyên gia đồng hành cùng bạn xây dựng kế hoạch hành động chi tiết để từng bước đạt được mục tiêu nghề nghiệp. Note: Trong quá trình thực hiện, nếu bạn gặp phải các rào cản tâm lý ảnh hưởng đến công việc (như mất động lực, tự tin thấp, áp lực/khủng hoảng...), chuyên gia sẽ tư vấn kết hợp các buổi tham vấn/trị liệu riêng lẻ để hỗ trợ bạn tốt nhất.
A16: 13 | B16: Dịch vụ | C16: Tham vấn cặp đôi diễn ra như thế nào? | D16: Buổi đầu để khám phá nhu cầu và mục đích: 30 phút riêng cho mỗi người, sau đó 30 phút cùng nhau (hoặc tách thành 2 buổi lẻ 60 phút). Bạn không cần tham gia cùng nhau ở buổi này, giúp mỗi người thoải mái hơn. Các buổi sau cả hai cùng tham gia, 90 phút/buổi. Nếu một trong hai cần tham vấn riêng, Wabi sẽ sắp xếp buổi riêng biệt. | E16: Trung bình | F16: Website · Inbox
A17: 14 | B17: Dịch vụ | C17: Wabi có dịch vụ bằng tiếng Anh không? | D17: Có. Wabi cung cấp tham vấn/trị liệu cho cả thân chủ trong nước và nước ngoài, bằng tiếng Việt và tiếng Anh. Ngoài ra một số therapist làm việc bằng tiếng Hàn (tham vấn cặp đôi Hàn–Việt), tiếng Quan Thoại và tiếng Quảng Đông. | E17: Trung bình | F17: Website · Inbox
A18: 15 | B18: Đánh giá | C18: Buổi đánh giá tâm lý diễn ra thế nào? | D18: Bạn làm việc trực tiếp với therapist trong 60 phút để họ hiểu rõ tình trạng của bạn và chọn các bài kiểm tra phù hợp. Therapist sẽ đưa ra kết luận ngay trong buổi, và gửi báo cáo chi tiết dạng PDF qua email trong vòng 7–10 ngày. | E18: Cao | F18: Website · Inbox | G18: Chia làm 3 bước cụ thể | H18: Quy trình đánh giá tâm lý ở Wabi được thực hiện chỉn chu qua 3 bước cụ thể: Bước 1: Bạn trao đổi sơ bộ về nhu cầu và/hoặc vấn đề hiện tại với chuyên viên tiếp nhận (admin của Wabi có chuyên môn về tâm lý học). Dựa trên các thông tin này, bạn sẽ nhận và hoàn thành các bài trắc nghiệm/thang đo tâm lý phù hợp trước buổi gặp chính thức với therapist. Bước 2: Therapist sẽ làm việc trực tiếp cùng bạn để khai thác sâu hơn về vấn đề hiện tại, lịch sử hình thành khó khăn, các yếu tố tác động... từ đó đưa ra nhận định chuyên môn và định hướng can thiệp nếu cần. (Lưu ý: một số trường hợp phức tạp hoặc nhiều thông tin, có thể cần 2 buổi làm việc với therapist). Bước 3: Sau 7–10 ngày, bạn sẽ nhận được báo cáo đánh giá tâm lý gửi qua email, bao gồm phân tích kết quả test, nhận định của nhà tâm lý và các khuyến nghị lộ trình tiếp theo. Sau khi nhận báo cáo, nếu có câu hỏi hay thắc mắc, bạn hoàn toàn có thể liên hệ với Wabi để được giải đáp và hỗ trợ.
A19: 16 | B19: Đánh giá | C19: Mình sẽ làm những bài test nào? | D19: Therapist chọn bài phù hợp với bạn. Thường gặp: Big5 (đo nhân cách — có độ tin cậy và tính khoa học hơn MBTI), test đa trí thông minh (thế mạnh bẩm sinh theo 9 nhóm năng lực), test lòng tự trọng Sorensen, thang cảm nhận hạnh phúc Carol Ryff, cùng các thang lâm sàng chuẩn hóa như DASS-21, Beck, Zung khi cần. | E19: Cao | F19: Website · Inbox | G19: Câu hỏi: Các bài test nào thường được sử dụng ở Wabi? | H19: Tùy thuộc vào nhu cầu và mô tả vấn đề ban đầu của bạn, Wabi sẽ gợi ý các bài test chuẩn hóa phù hợp. Trong quá trình đồng hành, nhà trị liệu có thể đề xuất thêm một số công cụ đánh giá khác để có bức tranh toàn diện nhất. Các bài test thường được sử dụng bao gồm: - Sức khỏe tinh thần: Đo lường mức độ trầm cảm (BDI-II), lo âu (Zung/GAD-7), lưỡng cực (MDQ), sang chấn tâm lý (PCL-5)... - Tính cách và nhận thức bản thân: Trắc nghiệm nhân cách Big Five, trắc nghiệm đa trí thông minh (Howard Gardner), Đánh giá chỉ số trí tuệ (IQ)... - Chất lượng sống và cảm xúc: Đánh giá lòng tự trọng (Sorensen), Đo lường mức độ hạnh phúc & sức khỏe tinh thần tổng thể (Carol Ryff)... Note: Các bài test tại Wabi chỉ đóng vai trò là công cụ hỗ trợ. Kết quả test luôn được therapist phân tích sâu và kết hợp với phỏng vấn lâm sàng để đảm bảo chính xác và khách quan.
A20: 17 | B20: Đánh giá | C20: File báo cáo PDF có bắt buộc không? Có tính phí riêng không? | D20: Chi phí đánh giá tâm lý tại Wabi chủ yếu nằm ở buổi gặp trực tiếp với therapist. File tổng hợp là phần hỗ trợ thêm — như một món quà bonus therapist dành tặng, không có cơ sở nào bắt buộc phải thực hiện. Vì vậy trong buổi bạn hoàn toàn có thể đặt câu hỏi trực tiếp và ghi âm lại nếu cần. | E20: Trung bình | F20: Website · Inbox | H20: - Không tính phí riêng: File báo cáo PDF tổng hợp kết quả đã được bao gồm trọn gói trong dịch vụ đánh giá tâm lý và bạn không phải trả thêm bất kỳ chi phí nào. - Không bắt buộc: Giá trị cốt lõi của dịch vụ nằm ở phiên làm việc 1:1 trực tiếp cùng therapist. File báo cáo là tài liệu hỗ trợ thêm để bạn lưu trữ và tham khảo sau buổi gặp. Trong buổi đánh giá, bạn hoàn toàn có thể chủ động đặt câu hỏi, ghi chú hoặc ghi âm lại các trao đổi quan trọng với therapist để thuận tiện cho việc xem lại sau đó.
A21: 18 | B21: Đánh giá | C21: Kết quả đánh giá có phải là chẩn đoán bệnh không? | D21: Không. Nhà tâm lý đưa ra đánh giá chuyên môn dựa trên các ngưỡng lâm sàng (ví dụ: bạn có triệu chứng của rối loạn trầm cảm và đã đạt ngưỡng lâm sàng 6–7 triệu chứng), nhưng việc đưa ra chẩn đoán chính thức mang tính phù hợp với hệ thống y tế là điều chỉ bác sĩ tâm thần làm được. | E21: Cao | F21: Website · Inbox | H21: Không. Kết quả đánh giá tại Wabi là nhận định chuyên môn về mặt tâm lý, không thay thế cho chẩn đoán y khoa chính thức. Therapist sẽ giúp bạn xác định các biểu hiện tâm lý hiện tại có đang chạm hoặc vượt ngưỡng lâm sàng hay không (ví dụ: mức độ trầm cảm, lo âu...), từ đó xây dựng lộ trình trị liệu phù hợp. Còn chẩn đoán y khoa chính thức (để cấp đơn thuốc hoặc phục vụ hồ sơ bệnh án y tế) thuộc thẩm quyền chuyên môn của bác sĩ tâm thần. Nếu kết quả đánh giá cho thấy bạn cần kết hợp điều trị y khoa/dùng thuốc, Wabi sẽ chủ động khuyến khích bạn đi thăm khám và hỗ trợ kết nối bạn với các bác sĩ tâm thần hoặc cơ sở y tế uy tín.
A22: 19 | B22: Chuyên môn | C22: Nhà tâm lý và bác sĩ tâm thần khác nhau thế nào? | D22: Nhà tâm lý lâm sàng (Thạc sĩ Tâm lý học Lâm sàng trở lên) được đào tạo để đánh giá sức khỏe tâm thần, nhận diện và phân biệt các rối loạn, đưa ra hướng dẫn hỗ trợ chăm sóc y tế (phối hợp với bác sĩ tâm thần), và thực hành các liệu pháp giúp bạn hiểu và quản lý vấn đề. Bác sĩ tâm thần là người đưa ra chẩn đoán chính thức, kê thuốc và các can thiệp y tế. | E22: Cao | F22: Website · Inbox
A23: 20 | B23: Chuyên môn | C23: Therapist của Wabi có bằng cấp gì? | D23: Hầu hết đội ngũ Wabi là Thạc sĩ Tâm lý học Lâm sàng, tốt nghiệp từ các trường trong nước (ĐHQG Hà Nội, ĐH KHXH&NV) và quốc tế (ĐH Sussex – Anh, ĐH Western Sydney – Úc, Russian State Social University – Nga, ĐH Wrexham – Anh, ĐH Murdoch – Singapore). Nhiều người có 5–7 năm kinh nghiệm thực hành. | E23: Cao | F23: Website · Inbox
A24: 21 | B24: Chuyên môn | C24: Wabi dùng những liệu pháp nào? | D24: Đội ngũ Wabi thực hành đa dạng: CBT (nhận thức – hành vi), DBT (biện chứng hành vi), ACT (chấp nhận & cam kết), Person-Centered (nhân vị trọng tâm), Psychodynamic & Psychoanalysis (tâm động học, phân tâm), IFS (hệ thống gia đình nội tâm), EFT/EFIT (tập trung cảm xúc), Gestalt, MI (phỏng vấn động lực), MBCT/MBSR/MiCBT (chánh niệm), CPT, BA (hoạt hóa hành vi), SFBT (giải pháp ngắn hạn), Art as Therapy. | E24: Trung bình | F24: Website | H24: Tùy thuộc vào chuyên môn đào tạo, định hướng cá nhân của từng therapist, cũng như đặc điểm nhân cách, nhận thức và vấn đề cụ thể của bạn, therapist sẽ linh hoạt áp dụng các liệu pháp hoặc kỹ thuật phù hợp nhất. Đội ngũ therapist ở Wabi thực hành đa dạng các tiếp cận chuẩn hóa quốc tế, bao gồm: - Trường phái Nhận thức - hành vi và Chánh niệm: CBT, DBT, ACT, MBCT/MBSR/MiCBT, BA, CPT (xử lý sang chấn). - Trường phái Nhân văn và tập trung vào cảm xúc: Person-Centered (nhân vị trọng tâm), EFT/EFIT (trị liệu tập trung vào cảm xúc), Gestalt, MI (phỏng vấn tạo động lực). - Trường phái Sâu sắc và nội tâm: Psychodynamic (tâm động học), Psychoanalysis (phân tâm học), IFS (hệ thống gia đình nội tâm). - Trường phái Ngắn hạn sáng tạo: SFBT (trị liệu tập trung vào giải pháp), Art as Therapy (trị liệu qua nghệ thuật).
A25: 22 | B25: Chọn therapist | C25: Làm sao để chọn therapist phù hợp? | D25: Chia sẻ với admin về tuổi, nơi sinh sống, vấn đề bạn đang gặp và kỳ vọng của bạn về therapist. Wabi sẽ gợi ý người có chuyên môn khớp nhất — ví dụ có therapist chuyên về attachment styles, có người chuyên PTSD, có người chuyên tâm lý học đường. Bạn cũng có thể nói rõ nếu có preference riêng (giới tính, độ tuổi, phong cách làm việc). | E25: Cao | F25: Inbox | H25: Để kết nối với therapist phù hợp, bạn chỉ cần chia sẻ ngắn gọn với chuyên viên tiếp nhận (admin) của Wabi về: - Vấn đề và kỳ vọng: những khó khăn bạn đang gặp phải và mục tiêu bạn muốn đạt được. Wabi sẽ tiến hành đối chiếu chuyên môn để gợi ý therapist có thế mạnh phù hợp nhất (như chuyên sâu về sang chấn/PTSD, phong cách gắn bó, tâm lý học đường, mâu thuẫn trong mối quan hệ...). - Sở thích và tình trạng cá nhân: bạn hoàn toàn có thể yêu cầu về giới tính, độ tuổi, đặc điểm giao tiếp, phong cách làm việc (sắc bén/định hướng hay ấm áp/lắng nghe), cũng như hình thức gặp (online hay trực tiếp)... với therapist Tuy nhiên, sự kết nối an toàn và tin tưởng mới là yếu tố quyết định hiệu quả trị liệu. Nếu sau 1-2 buổi bạn cảm thấy phong cách làm việc chưa thật sự phù hợp, Wabi luôn sẵn sàng hỗ trợ bạn đổi sang một therapist khác.
A26: 23 | B26: Chọn therapist | C26: Nếu mình thấy không hợp với therapist thì sao? | D26: Bạn hoàn toàn có thể đổi therapist nếu cảm thấy cần thiết. Việc không 'connect' được với một người không có nghĩa là therapy không hiệu quả với bạn — mối quan hệ trị liệu là yếu tố quan trọng bậc nhất. Nếu có vấn đề gì (khó hiểu, không kết nối được), bạn có thể nhắn admin hoặc feedback trực tiếp cho therapist. | E26: Cao | F26: Website · Inbox | H26: Bạn hoàn toàn có quyền đề xuất thay đổi nhà trị liệu bất kỳ lúc nào. Sự kết nối an toàn và tin tưởng giữa thân chủ và nhà trị liệu là yếu tố quyết định phần lớn hiệu quả trị liệu. Việc chưa tìm được sự đồng điệu với một nhà trị liệu không có nghĩa là liệu pháp tâm lý không hiệu quả với bạn, mà đơn giản là hai bên chưa "cùng tần số". Khi cảm thấy mình không phù hợp hoặc thoải mái trong phiên làm việc, bạn có thể: - Phản hồi trực tiếp với therapist về cảm giác chưa phù hợp. Các therapist tại Wabi luôn đón nhận phản hồi với sự cởi mở, tôn trọng, không phán xét và sẵn sàng điều chỉnh phong cách hoặc chủ động giới thiệu bạn đến một đồng nghiệp phù hợp hơn. - Nếu bạn cảm thấy ngại nói trực tiếp, chỉ cần nhắn cho Admin. Wabi sẽ lắng nghe mong muốn của bạn và hỗ trợ chuyển đổi sang một nhà trị liệu khác hoàn toàn riêng tư và thoải mái. Tại Wabi, sự thoải mái và tiến trình phục hồi của bạn luôn là ưu tiên hàng đầu. Bạn không bao giờ phải lo lắng về việc làm ai đó buồn hay mất lòng khi đề xuất thay đổi.
A27: 24 | B27: Quy trình | C27: Tham vấn online hay offline? | D27: Cả hai. Online qua Google Meet, hoặc trực tiếp tại địa điểm của therapist (Hà Nội và TP.HCM). Một số therapist chỉ làm online. Buổi offline thường có phụ thu thêm. | E27: Cao | F27: Website · Inbox | H27: Cả hai. Các therapist của Wabi làm việc Online qua nền tảng Google Meet, hoặc trực tiếp tại địa điểm của therapist (Hà Nội và TP.HCM). Một số therapist chỉ làm online. Các phiên làm việc offline thường có phụ thu thêm do Wabi phải chi trả chi phí thuê phòng tham vấn cho bên thứ ba.
A28: 25 | B28: Quy trình | C28: Online có hiệu quả bằng offline không? | D28: Nhiều nghiên cứu quốc tế cho thấy tham vấn online có hiệu quả tương đương gặp trực tiếp với phần lớn các vấn đề tâm lý phổ biến như lo âu và trầm cảm. Điều quan trọng là bạn có không gian riêng tư và cảm thấy thoải mái. Với một số trường hợp (trẻ nhỏ, khủng hoảng cấp tính), gặp trực tiếp có thể phù hợp hơn. | E28: Trung bình | F28: Website · Inbox | H28: Có. Nhiều nghiên cứu quốc tế đã chứng minh tham vấn/trị liệu Online mang lại hiệu quả tương đương với gặp trực tiếp đối với hầu hết các vấn đề tâm lý phổ biến như lo âu, trầm cảm hay stress. - Trị liệu Online phù hợp khi bạn bận rộn, di chuyển khó khăn, ở xa trung tâm, hoặc cảm thấy thoải mái/an toàn nhất khi chia sẻ tại không gian quen thuộc của mình (chỉ cần chuẩn bị không gian riêng tư và kết nối internet ổn định). - Gặp trực tiếp (Offline) khuyến nghị khi: đối tượng là trẻ nhỏ, hoặc trường hợp đang trong giai đoạn khủng hoảng cấp tính, sang chấn quá nặng cần sự hiện diện thể lý trực tiếp của therapist. Dù chọn hình thức nào, yếu tố cốt lõi quyết định hiệu quả vẫn là sự kết nối an toàn giữa bạn và nhà trị liệu cùng sự cam kết trong suốt quá trình đồng hành.
A29: 26 | B29: Quy trình | C29: Mình phải làm bao nhiêu buổi? | D29: Tại Wabi không có quy định về số buổi cố định. Bạn có thể hẹn therapist linh hoạt — hàng tuần, hàng tháng, hoặc bất cứ khi nào bạn cảm thấy cần. Số buổi phù hợp phụ thuộc vào vấn đề và mục tiêu của bạn; therapist sẽ trao đổi với bạn về lộ trình gợi ý sau buổi đầu tiên. | E29: Cao | F29: Website · Inbox | G29: Câu hỏi: Mình cần tham gia bao nhiêu buổi trị liệu? | H29: Tại Wabi không có quy định số buổi bắt buộc cố định. Lộ trình trị liệu sẽ được thiết kế riêng tùy thuộc vào vấn đề, mong muốn và mục tiêu của bạn. Sau buổi gặp đầu tiên, therapist sẽ trao đổi và đề xuất lộ trình phù hợp với bạn. Thông thường, bạn có thể tham khảo khung thời gian phổ biến sau: - Ngắn hạn (4–6 buổi): Phù hợp để giải quyết các khó khăn cụ thể ở hiện tại, học kỹ năng ứng phó căng thẳng hoặc định hướng vấn đề. - Trung và dài hạn (12 buổi trở lên): Phù hợp với các tổn thương sâu sắc, các rối nhiễu tâm lý hoặc nhu cầu tái cấu trúc bản thân toàn diện. - Tần suất linh hoạt: Thường là 1 buổi/tuần ở giai đoạn đầu, sau đó có thể giãn cách ra 2 tuần/buổi hoặc hàng tháng khi tình trạng của bạn đã ổn định. Bạn luôn là người chủ động quyết định việc tiếp tục, điều chỉnh tần suất hay dừng quá trình trị liệu dựa trên sự bàn bạc và thống nhất với therapist.
A30: 27 | B30: Quy trình | C30: Screening là gì? Vì sao mình phải trả lời? | D30: Trước buổi, Wabi hỏi bạn vài câu ngắn về ăn/ngủ trong tháng qua, điều khiến bạn khó chịu nhất, kỳ vọng của bạn về therapist và tóm tắt tình trạng hiện tại. Việc này giúp therapist chuẩn bị tốt hơn và chọn hướng tiếp cận phù hợp ngay từ buổi đầu, thay vì mất thời gian hỏi lại. | E30: Cao | F30: Inbox | H30: Screening là một bảng câu hỏi ngắn gọn (thường mất 3–5 phút trả lời) được gửi đến bạn trước buổi hẹn chính thức, về tình trạng của bạn hiện tại, các yếu tố nguy cơ, điều khiến bạn lo lắng hay băn khoăn và kỳ vọng về therapist. Việc hoàn thành screening không chỉ giúp Wabi kết nối bạn với therapist phù hợp mà còn giúp therapist nắm được thông tin ban đầu trước khi bước vào phòng tham vấn, nhận diện sớm các dấu hiệu khủng hoảng nếu có để chuẩn bị phương án hỗ trợ an toàn và kịp thời nhất cho bạn.
A31: 28 | B31: Quy trình | C31: Wabi gửi lịch qua đâu? Mình cần làm gì? | D31: Admin gửi lịch qua email. Nếu Wabi gửi bài test trước buổi, bạn làm xong có thể nhắn admin để therapist xem kết quả trước. | E31: Cao | F31: Inbox
A32: 29 | B32: Quy trình | C32: Mình muốn đổi lịch thì sao? | D32: Bạn nhắn admin muộn nhất trước 3 tiếng so với giờ hẹn. Nếu báo muộn hơn, therapist vẫn tính phí như bình thường. Vì Wabi không thu cọc trước, tụi mình rất mong bạn không huỷ lịch sát giờ. | E32: Cao | F32: Website · Inbox
A33: 30 | B33: Quy trình | C33: Sau buổi mình nhận được gì? | D33: Nếu bạn làm Đánh giá tâm lý: báo cáo chi tiết dạng PDF gửi qua email trong 7–10 ngày. Nếu bạn tham vấn/trị liệu: therapist xây dựng Kế hoạch can thiệp (Treatment Plan); nếu bạn có yêu cầu xem xét, therapist có thể hỗ trợ hoàn thành trong vòng 5 ngày. | E33: Cao | F33: Website · Inbox | H33: Sau buổi làm việc tại Wabi, bạn sẽ nhận được cả những giá trị thực tế cả trong và sau phiên: 1. Trong phiên làm việc: - Một không gian an toàn và không phán xét, nơi bạn được trút bỏ gánh nặng cảm xúc, được lắng nghe và thấu hiểu hoàn toàn. - Nhìn nhận rõ ràng hơn về vấn đề đang gặp phải: bạn và therapist cùng bóc tách, nhìn nhận lại khó khăn dưới góc nhìn khách quan, khoa học. - Công cụ và bài tập ứng phó: được giới thiệu, hướng dẫn các kỹ thuật thực hành (quản lý lo âu, căng thẳng, điều hòa thần kinh, giao tiếp...) để áp dụng ngay vào đời sống hàng ngày. - Bớt mơ hồ về trạng thái của bản thân và biết rõ mình cần làm gì tiếp theo. 2. Tài liệu hỗ trợ - Với dịch vụ đánh giá tâm lý: bạn sẽ nhận được báo cáo đánh giá chi tiết (file PDF) tổng hợp kết quả test và nhận định chuyên môn gửi qua email sau 7–10 ngày. - Với tiến trình tham vấn/trị liệu: therapist sẽ xây dựng kế hoạch can thiệp/điều trị cá nhân hóa. Nếu bạn có nhu cầu xem hoặc lưu trữ bản kế hoạch này, therapist sẽ hoàn thiện và gửi bạn trong vòng 5 ngày sau khi nhận được yêu cầu.
A34: 31 | B34: Quy trình | C34: Mình đặt lịch buổi tiếp theo thế nào? | D34: Ba cách: trao đổi trực tiếp với therapist ngay cuối buổi để chốt lịch tuần tới; nhắn admin qua Hotline/Zalo/Instagram để được sắp xếp lịch trống mới nhất; hoặc đổi therapist nếu bạn cảm thấy cần thiết. | E34: Trung bình | F34: Website · Inbox | H34: Bạn có thể đặt lịch tiếp theo linh hoạt bằng một trong các cách dưới đây: - Trao đổi trực tiếp với therapist ngay cuối buổi để chốt lịch tuần tới - Nhắn admin qua Hotline/Zalo/Instagram để được sắp xếp lịch trống mới nhất hoặc đổi therapist nếu bạn cảm thấy cần thiết.
A35: 33 | B35: Chi phí | C35: Wabi có gói ưu đãi không? | D35: Có. Gói Đồng Hành: combo 8 buổi trị liệu giảm ngay 10% tổng phí. Lợi ích không chỉ là tiết kiệm chi phí mà còn giúp bạn giữ lịch cố định với chuyên gia, tạo sự ổn định và an tâm trong suốt quá trình. Hướng nghiệp cũng đang có ưu đãi theo gói. | E35: Cao | F35: Website · Inbox
A36: 36 | B36: Chi phí | C36: Mình không đủ tiền đi therapy thì sao? | D36: Wabi có chương trình dành cho bạn ở Hà Nội: uống đủ 10 ly cà phê tại Onion Cafe → được 1 buổi tham vấn tâm lý miễn phí. Ngoài ra, các đường dây nóng miễn phí như Ngày Mai (096 306 1414) hay Tổng đài 111 luôn sẵn sàng lắng nghe bạn. | E36: Cao | F36: Website · Social
A37: 37 | B37: Onion Cafe | C37: Chương trình 10 ly cà phê là gì? | D37: Uống đủ 10 ly cà phê tại Onion Cafe → được 1 buổi tham vấn tâm lý miễn phí. Không phải clickbait — Wabi làm thật. Chương trình dành cho các bạn tại Hà Nội. Wabi biết nhiều người đang cần nói chuyện với ai đó nhưng chưa sẵn sàng, chưa đủ tiền, hoặc chỉ đơn giản là chưa dám. Thì cứ uống cà phê đã, tích từ từ. Ghé Onion Cafe tại 4 Ngõ 46A Phạm Ngọc Thạch, Hà Nội → báo họ tên và số điện thoại khi order → Wabi tích ly tự động cho bạn. Bạn không cần nhớ hay giữ thẻ gì cả. | E37: Cao | F37: Website · Social
A38: 39 | B38: Trẻ vị thành niên | C38: Dưới 18 tuổi có tham gia được không? | D38: Được, nhưng cần có sự đồng ý của phụ huynh. Bạn chỉ cần chụp màn hình đồng ý của phụ huynh và chia sẻ số Zalo của phụ huynh với admin là được. | E38: Cao | F38: Website · Inbox
A39: 40 | B39: Trẻ vị thành niên | C39: Phụ huynh có được biết nội dung buổi tham vấn không? | D39: Wabi tin rằng việc kết nối và chia sẻ thông tin với gia đình sẽ mang lại hiệu quả tốt hơn cho hành trình hỗ trợ. Với thân chủ vị thành niên, Wabi sắp xếp để chuyên gia liên hệ trao đổi với phụ huynh về tiến trình — trong khuôn khổ giữ được không gian an toàn và sự tin tưởng của bạn. Nội dung chi tiết trong buổi vẫn được bảo mật ở mức tối đa có thể. | E39: Cao | F39: Inbox | G39: Thêm cụm từ nếu tôi dưới 18 tuổi,... | H39: Có, nhưng ở mức độ phù hợp và tôn trọng nguyên tắc bảo mật của thân chủ. Tại Wabi, sự riêng tư của thân chủ luôn được tôn trọng để các bạn cảm thấy an toàn khi chia sẻ, dù bạn bao nhiêu tuổi. Quy trình đồng hành cùng phụ huynh được thực hiện như sau: - Bảo mật chi tiết cuộc trò chuyện: therapist không tiết lộ chi tiết từng lời nói hay nhật ký, suy nghĩ riêng tư của thân chủ cho phụ huynh, trừ khi có sự đồng ý của thân chủ. - Cập nhật tiến trình và khuyến nghị cho phụ huynh: therapist sẽ trao đổi với phụ huynh về bức tranh toàn cảnh, sự tiến bộ, cũng như hướng dẫn phụ huynh cách phối hợp, tương tác với thân chủ để hỗ trợ tiến trình phục hồi tốt nhất. - Ngoại lệ phá vỡ nguyên tắc bảo mật: therapist bắt buộc phải thông báo ngay cho phụ huynh/người giám hộ trong trường hợp phát hiện nguy cơ thân chủ tự hại, gây hại cho người khác hoặc đang trong tình trạng nguy hiểm cấp tính. Trước khi bắt đầu tiến trình, Wabi/therapist sẽ có một buổi thống nhất rõ ràng về ranh giới bảo mật giữa phụ huynh – thân chủ – nhà trị liệu để tất cả các bên đều cảm thấy an tâm và được tôn trọng.
A40: 41 | B40: Bảo mật | C40: Thông tin của mình có được giữ kín không? | D40: Có. Wabi là không gian an toàn, riêng tư và thấu cảm. Mọi thông tin bạn chia sẻ với therapist được bảo mật theo nguyên tắc đạo đức nghề nghiệp. Ngoại lệ hiếm hoi theo chuẩn quốc tế là khi có nguy cơ nghiêm trọng đến tính mạng của bạn hoặc người khác — trong trường hợp đó therapist sẽ trao đổi với bạn trước. | E40: Cao | F40: Website · Inbox | H40: Có. Wabi cam kết bảo mật tuyệt đối các thông tin của bạn. Tại Wabi, nguyên tắc bảo mật là nguyên tắc cao nhất và bắt buộc tuân thủ với tất cả therapist. Tất cả thông tin cá nhân, nội dung trao đổi, bài test tâm lý và hồ sơ trị liệu của bạn đều được lưu trữ an toàn và chỉ có therapist trực tiếp đồng hành cùng bạn mới được tiếp cận, trừ khi có sự đồng ý của bạn (hoặc người đại diện hợp pháp). Các trường hợp ngoại lệ bắt buộc: việc bảo mật thông tin chỉ có thể bị phá vỡ trong các trường hợp đặc biệt sau nhằm đảm bảo sự an toàn cho bạn và cộng đồng: - Khi therapist nhận thấy có nguy cơ rõ ràng và cấp thiết về việc bạn có hành vi tự hại/tự sát hoặc gây hại đến tính mạng, sức khỏe của người khác. - Khi có lệnh hoặc yêu cầu chính thức từ cơ quan tư pháp/tòa án theo quy định của pháp luật hiện hành. - Khi phát hiện các hành vi ngược đãi, xâm hại hoặc bạo hành đối với trẻ em, người khuyết tật, người cao tuổi hoặc người không có năng lực hành vi dân sự và các hành vi vi phạm pháp luật khác. Ngay cả trong các trường hợp ngoại lệ bắt buộc, therapist sẽ thảo luận trước với bạn (nếu điều kiện cho phép) và chỉ chia sẻ đúng phần thông tin tối thiểu cần thiết để đảm bảo sự an toàn.
A41: 42 | B41: Bảo mật | C41: Wabi có kê thuốc không? | D41: Không. Nhà tâm lý không kê thuốc — đó là việc của bác sĩ tâm thần. Nếu tình trạng của bạn cần can thiệp y tế, Wabi sẽ kết nối bạn với bác sĩ và đánh giá của nhà tâm lý sẽ là cơ sở tốt để bạn trao đổi với bác sĩ. | E41: Cao | F41: Website · Inbox | H41: Không. Kê đơn và can thiệp y tế thuộc thẩm quyền chuyên môn của các bác sĩ tâm thần. Các therapist tại Wabi tập trung vào đánh giá tâm lý, tham vấn và trị liệu bằng các liệu pháp tâm lý. Nếu tình trạng của bạn cần can thiệp y tế/dùng thuốc, therapist sẽ thảo luận và đề xuất bạn thăm khám chuyên khoa tâm thần; Wabi sẽ hỗ trợ cung cấp địa chỉ của các bác sĩ tâm thần/cơ sở y tế uy tín nếu bạn cần. Đồng thời, báo cáo đánh giá tâm lý tại Wabi có thể là cơ sở thông tin chuyên môn giúp bác sĩ tâm thần hiểu nhanh và rõ ràng về tình trạng của bạn. Trị liệu tâm lý và điều trị y khoa bằng thuốc không loại trừ nhau. Việc kết hợp song song cả hai phương pháp thường mang lại hiệu quả tối ưu cho các trường hợp có triệu chứng từ trung bình đến nặng.
...

Sheet TEXT EDITED
A1: TEXT CŨ | B1: TEXT MỚI
A2: Wabi là không gian an toàn, riêng tư và thấu cảm — nơi bạn bắt đầu hành trình chăm sóc sức khỏe tinh thần một cách nhẹ nhàng, đúng với chính mình. Online & offline tại Hà Nội và TP.HCM.
A3: An toàn & riêng tư Mọi chia sẻ của bạn được giữ kín tuyệt đối. Không phán xét, chỉ có lắng nghe và thấu hiểu.
A4: Đồng hành linh hoạt Không quy định số buổi cố định, không cọc trước. Bạn hẹn theo nhịp của mình — tuần, tháng, hay khi cần.
A5: Mỗi vết thương tâm hồn đều xứng đáng được lắng nghe và chăm sóc. Wabi có những nhà trị liệu sẵn sàng ở đây, đi cùng bạn nhẹ nhàng từng bước.
A11: NOTE
A12: Bỏ Art Therapy. Thêm các Dịch vụ sau: | B12: Description
A13: Employment Asssistant Program | B13: Đồng hành cùng doanh nghiệp trong việc xây dựng văn hóa quan tâm đến con người thông qua các giải pháp chăm sóc sức khỏe tâm thần dựa trên cơ sở khoa học và phù hợp với bối cảnh thực tiễn.
A14: Low cost therapy | B14: Chương trình Hỗ trợ (Low-cost therapy) mang đến giải pháp hỗ trợ thiết thực với mức phí giảm 20% so với thông thường, dành riêng cho học sinh và sinh viên dưới 20 tuổi hoặc các bạn đang gặp khó khăn về tài chính
A15: Workshop | B15: Chú trọng sự kết hợp giữa lý thuyết nền tảng và thực hành trải nghiệm, giúp bạn mang về những giá trị ứng dụng thực tế. Dưới sự dẫn dắt của thạc sĩ tâm lý/nhà trị liệu, mỗi buổi học sẽ cung cấp kiến thức chuyên ngành và kỹ năng cụ thể—từ thiết lập ranh giới, nhận diện kiểu gắn bó đến xoa dịu lo âu.
A16: Opentalk | B16: Không gian trò chuyện bình đẳng, tự do, không diễn giả hay áp lực phát biểu. Bạn có thể thoải mái lắng nghe hoặc lên tiếng khi sẵn sàng. Mỗi phiên thảo luận đều có chuyên viên tâm lý đồng hành để giữ vững không gian an toàn, bảo mật và nâng đỡ cảm xúc.

Sheet Tổng quan
A1: TỔNG QUAN THEO NHÓM CHỦ ĐỀ
A3: Nhóm chủ đề | B3: Số câu hỏi | C3: Số câu ưu tiên Cao
A4: Bắt đầu | B4: =COUNTIF(FAQ!$B$5:$B$48,$A4) -> 7 | C4: =COUNTIFS(FAQ!$B$5:$B$48,$A4,FAQ!$E$5:$E$48,"Cao") -> 7
A5: Dịch vụ | B5: =COUNTIF(FAQ!$B$5:$B$48,$A5) -> 6 | C5: =COUNTIFS(FAQ!$B$5:$B$48,$A5,FAQ!$E$5:$E$48,"Cao") -> 3
A6: Đánh giá | B6: =COUNTIF(FAQ!$B$5:$B$48,$A6) -> 4 | C6: =COUNTIFS(FAQ!$B$5:$B$48,$A6,FAQ!$E$5:$E$48,"Cao") -> 3
A7: Chuyên môn | B7: =COUNTIF(FAQ!$B$5:$B$48,$A7) -> 3 | C7: =COUNTIFS(FAQ!$B$5:$B$48,$A7,FAQ!$E$5:$E$48,"Cao") -> 2
A8: Chọn therapist | B8: =COUNTIF(FAQ!$B$5:$B$48,$A8) -> 2 | C8: =COUNTIFS(FAQ!$B$5:$B$48,$A8,FAQ!$E$5:$E$48,"Cao") -> 2
A9: Quy trình | B9: =COUNTIF(FAQ!$B$5:$B$48,$A9) -> 9 | C9: =COUNTIFS(FAQ!$B$5:$B$48,$A9,FAQ!$E$5:$E$48,"Cao") -> 7
A10: Chi phí | B10: =COUNTIF(FAQ!$B$5:$B$48,$A10) -> 2 | C10: =COUNTIFS(FAQ!$B$5:$B$48,$A10,FAQ!$E$5:$E$48,"Cao") -> 2
A11: Onion Cafe | B11: =COUNTIF(FAQ!$B$5:$B$48,$A11) -> 1 | C11: =COUNTIFS(FAQ!$B$5:$B$48,$A11,FAQ!$E$5:$E$48,"Cao") -> 1
A12: Trẻ vị thành niên | B12: =COUNTIF(FAQ!$B$5:$B$48,$A12) -> 2 | C12: =COUNTIFS(FAQ!$B$5:$B$48,$A12,FAQ!$E$5:$E$48,"Cao") -> 2
A13: Bảo mật | B13: =COUNTIF(FAQ!$B$5:$B$48,$A13) -> 2 | C13: =COUNTIFS(FAQ!$B$5:$B$48,$A13,FAQ!$E$5:$E$48,"Cao") -> 2
A14: Hiệu quả | B14: =COUNTIF(FAQ!$B$5:$B$48,$A14) -> 3 | C14: =COUNTIFS(FAQ!$B$5:$B$48,$A14,FAQ!$E$5:$E$48,"Cao") -> 2
A15: Sau buổi | B15: =COUNTIF(FAQ!$B$5:$B$48,$A15) -> 1 | C15: =COUNTIFS(FAQ!$B$5:$B$48,$A15,FAQ!$E$5:$E$48,"Cao") -> 0
... A17: Khác | B17: =COUNTIF(FAQ!$B$5:$B$48,$A17) -> 0 | C17: =COUNTIFS(FAQ!$B$5:$B$48,$A17,FAQ!$E$5:$E$48,"Cao") -> 0
A18: TỔNG | B18: =SUM(B4:B17) -> 44 | C18: =SUM(C4:C17) -> 35
A20: Ghi chú:
A21: • 'Ưu tiên Cao' = câu nên đưa lên website và dùng làm mẫu trả lời inbox nhanh.
A22: • Nội dung nghiệp vụ (giá, quy trình, therapist, chương trình Onion Cafe) lấy từ tài liệu nội bộ Wabi do người dùng cung cấp.
A23: • Các câu về hiệu quả therapy online, kỳ thị therapy, bảo mật và ngoại lệ bảo mật được viết theo thông lệ phổ biến của
A24: các nền tảng quốc tế (APA, Psychology Today, BetterHelp, Beyond Blue, Headspace AU) — cần đội ngũ chuyên môn Wabi rà soát trước khi đăng.
A25: • Số điện thoại hotline cần kiểm tra lại tính cập nhật định kỳ (khuyến nghị 6 tháng/lần).
